Workbook

Sheet Faturamento
A1: Rendimento Final: | B1: =SUM(Dezembro!B3) -> 4770.16
A2: Total de Gastos: | B2: =SUM(Janeiro!E13,Fevereiro!E12,Março!E12,Abril!E12,Maio!E13,Junho!E13,Julho!E13,Agosto!E13,Setembro!E13,Outubro!E13,Novembro!E13,Dezembro!E13) -> 44689.88
A3: Total de Ganhos: | B3: =SUM(Janeiro!K13,Fevereiro!K12,Março!K12,Abril!K12,Maio!K13,Junho!K13,Julho!K13,Agosto!K13,Setembro!K13,Outubro!K13,Novembro!K13,Dezembro!K13) -> 40797.65
A4: Rendimento último ano: | B4: 0
A5: Saldo Atual: | B5: 0

Sheet Janeiro
B2: RENDIMENTO | D2: SALDO | G2: Total: | J2: =SUM(E4:E8) -> 29.02 | M2: Cartões | T2: Despesas de Casa
B3: =SUM(Faturamento!B5,K13-E13) -> 29.02 | G3: Diferença: | J3: =SUM(J2-B3) -> -4.3698378e-13
D4: Inter | E4: 0 | N4: Divida Cartões: | O4: =SUM(N7:R11) -> 7519.18 | T4: DESCRIÇÃO | U4: VENCIMENTO | V4: VALOR | W4: PAGO | X4: TOTAL: | Y4: =SUM(V5:V21) -> 600.14 | AA4: CEMIG
D5: 99Pay | E5: 0 | G5: Renda: | J5: =J16 -> 3462.94 | T5: Internet | V5: 189.9 | X5: PAGO: | Y5: =SUM(W5:W21) -> 0
B6: PREVISTO | D6: NuBank | E6: 0 | N6: Inter | O6: Santander | P6: Mercado Pago | Q6: NuBank | R6: PicPay | T6: Copasa | V6: 159.75 | X6: FALTA: | Y6: =SUM(Y4-Y5) -> 600.14 | AA6: Nº Cliente: | AB6: 7003157185
B7: =SUM(J13-D13)+Faturamento!B5 -> -63.808 | D7: Mercado Pago | E7: 29.02 | G7: Investimento | J7: =SUM(J5*15)/100 -> 519.441 | M7: Augusto | N7: =SUMIFS(Tabela41012151821242730333941[Valor],Tabela41012151821242730333941[Pagador],"Augusto",Tabela41012151821242730333941[Banco],"Inter") -> 0 | O7: =SUMIFS(Tabela41012151821242730333941[Valor],Tabela41012151821242730333941[Pagador],"Augusto",Tabela41012151821242730333941[Banco],"Santander") -> 0 | P7: =SUMIFS(Tabela41012151821242730333941[Valor],Tabela41012151821242730333941[Pagador],"Augusto",Tabela41012151821242730333941[Banco],"Mercado Pago") -> 0 | Q7: =SUMIFS(Tabela41012151821242730333941[Valor],Tabela41012151821242730333941[Pagador],"Augusto",Tabela41012151821242730333941[Banco],"NuBank") -> 0 | R7: =SUMIFS(Tabela41012151821242730333941[Valor],Tabela41012151821242730333941[Pagador],"Augusto",Tabela41012151821242730333941[Banco],"PicPay") -> 0 | T7: Cemig | V7: 250.49 | AA7: Nº Instalação: | AB7: 3001236814
D8: Carteira | E8: 0 | G8: Depesas | J8: =SUM(K16*65)/100 -> 2250.911 | M8: Amor | N8: =SUMIFS(Tabela41012151821242730333941[Valor],Tabela41012151821242730333941[Pagador],"Anna",Tabela41012151821242730333941[Banco],"Inter") -> 0 | O8: =SUMIFS(Tabela41012151821242730333941[Valor],Tabela41012151821242730333941[Pagador],"Anna",Tabela41012151821242730333941[Banco],"Santander") -> 0 | P8: =SUMIFS(Tabela41012151821242730333941[Valor],Tabela41012151821242730333941[Pagador],"Anna",Tabela41012151821242730333941[Banco],"Mercado Pago") -> 2718.11 | Q8: =SUMIFS(Tabela41012151821242730333941[Valor],Tabela41012151821242730333941[Pagador],"Anna",Tabela41012151821242730333941[Banco],"NuBank") -> 0 | R8: =SUMIFS(Tabela41012151821242730333941[Valor],Tabela41012151821242730333941[Pagador],"Anna",Tabela41012151821242730333941[Banco],"PicPay") -> 0 | X8: DIVISÃO | AA8: CPF: | AB8: 276.006.966-49
D9: Cofrinho | E9: 0 | G9: Diferença mês | J9: =SUM(K13-E13) -> 29.02 | M9: Lila | N9: =SUMIFS(Tabela41012151821242730333941[Valor],Tabela41012151821242730333941[Pagador],"Lila",Tabela41012151821242730333941[Banco],"Inter") -> 0 | O9: =SUMIFS(Tabela41012151821242730333941[Valor],Tabela41012151821242730333941[Pagador],"Lila",Tabela41012151821242730333941[Banco],"Santander") -> 0 | P9: =SUMIFS(Tabela41012151821242730333941[Valor],Tabela41012151821242730333941[Pagador],"Lila",Tabela41012151821242730333941[Banco],"Mercado Pago") -> 568.88 | Q9: =SUMIFS(Tabela41012151821242730333941[Valor],Tabela41012151821242730333941[Pagador],"Lila",Tabela41012151821242730333941[Banco],"NuBank") -> 0 | R9: =SUMIFS(Tabela41012151821242730333941[Valor],Tabela41012151821242730333941[Pagador],"Lila",Tabela41012151821242730333941[Banco],"PicPay") -> 0 | X9: Augusto | Y9: =((Y4*70)/100)+Y18 -> 420.098
M10: Paula | N10: =SUMIFS(Tabela41012151821242730333941[Valor],Tabela41012151821242730333941[Pagador],"Paula",Tabela41012151821242730333941[Banco],"Inter") -> 0 | O10: =SUMIFS(Tabela41012151821242730333941[Valor],Tabela41012151821242730333941[Pagador],"Paula",Tabela41012151821242730333941[Banco],"Santander") -> 0 | P10: =SUMIFS(Tabela41012151821242730333941[Valor],Tabela41012151821242730333941[Pagador],"Paula",Tabela41012151821242730333941[Banco],"Mercado Pago") -> 0 | Q10: =SUMIFS(Tabela41012151821242730333941[Valor],Tabela41012151821242730333941[Pagador],"Paula",Tabela41012151821242730333941[Banco],"NuBank") -> 0 | R10: =SUMIFS(Tabela41012151821242730333941[Valor],Tabela41012151821242730333941[Pagador],"Paula",Tabela41012151821242730333941[Banco],"PicPay") -> 0
M11: Claudio | N11: =SUMIFS(Tabela41012151821242730333941[Valor],Tabela41012151821242730333941[Pagador],"Claudio",Tabela41012151821242730333941[Banco],"Inter") -> 0 | O11: =SUMIFS(Tabela41012151821242730333941[Valor],Tabela41012151821242730333941[Pagador],"Claudio",Tabela41012151821242730333941[Banco],"Santander") -> 0 | P11: =SUMIFS(Tabela41012151821242730333941[Valor],Tabela41012151821242730333941[Pagador],"Claudio",Tabela41012151821242730333941[Banco],"Mercado Pago") -> 0 | Q11: =SUMIFS(Tabela41012151821242730333941[Valor],Tabela41012151821242730333941[Pagador],"Claudio",Tabela41012151821242730333941[Banco],"NuBank") -> 0 | R11: =SUMIFS(Tabela41012151821242730333941[Valor],Tabela41012151821242730333941[Pagador],"Claudio",Tabela41012151821242730333941[Banco],"PicPay") -> 4232.19 | X11: Carla | Y11: =((Y4*30)/100)+Y18 -> 180.042
B12: LANÇAMENTOS DO MÊS
B13: Total: | D13: =SUM(D16:D33) -> 18721.34 | E13: =SUM(E16:E33) -> 18721.34 | G13: Total: | J13: =SUM(J16:J31) -> 18657.532 | K13: =SUM(K16:K31) -> 18750.36 | N13: Descrição | O13: Valor | P13: Data | Q13: Pagador | R13: Banco
B14: DESPESAS | G14: RECEBIMENTOS | N14: Prestão HB20s | O14: 1485.11 | P14: 46038 | Q14: Anna | R14: Mercado Pago
B15: DESCRIÇÃO | C15: TIPO | D15: PREVISTO | E15: PAGO | G15: DESCRIÇÃO | H15: PAGADOR | I15: TIPO | J15: PREVISTO | K15: RECEBIDO | N15: Plano de saúde Anna | O15: 200 | P15: 46029 | Q15: Anna | R15: Mercado Pago
B16: Theo | C16: Pensão | D16: 387 | E16: 387 | G16: Salário | H16: WKVE | I16: Renda | J16: 3462.94 | K16: 3462.94 | N16: Emprestimo Cartão | O16: 260 | P16: 46029 | Q16: Anna | R16: Mercado Pago
B17: Plano de Saúde - Mãe | C17: Despesa Pessoal | D17: 127.71 | E17: 127.71 | G17: Aluguel Notebook | H17: WKVE | I17: Renda | J17: 50 | K17: 50 | N17: Emprestimo Cartão | O17: 450 | P17: 46029 | Q17: Anna | R17: Mercado Pago
B18: Despesa de casa | C18: Despesas de Casa | D18: =SUM(V6:V7) -> 410.24 | E18: 410.24 | G18: Cartões Emprestados | H18: Claudio | I18: Cartão | J18: =SUM(N11:R11) -> 4232.19 | K18: 4232.19 | N18: Abastecimento | O18: 260 | P18: 46029 | Q18: Anna | R18: Mercado Pago
B19: Mercado Pago | C19: Cartões | D19: 1534.86 | E19: 1534.86 | G19: Cartões Emprestados | H19: Lila | I19: Cartão | J19: =SUM(N9:R9) -> 568.88 | K19: 568.88 | N19: tio Claudio | O19: 4232.19 | P19: 46029 | Q19: Claudio | R19: PicPay
B20: Inter | C20: Cartões | D20: 7540.44 | E20: 7540.44 | G20: Cartões Emprestados | H20: Anna | I20: Cartão | J20: =SUM(N8:R8) -> 2718.11 | K20: 2670 | N20: Compras Praia | O20: 30 | P20: 46032 | Q20: Lila | R20: Mercado Pago
B21: Santander | C21: Cartões | D21: 519.29 | E21: 519.29 | G21: Despesa de casa | H21: Carla | I21: Despesas de Casa | J21: =Y11 -> 180.042 | K21: 320.98 | N21: Posto chefão | O21: 265.9 | P21: 46032 | Q21: Lila | R21: Mercado Pago
B22: PicPay | C22: Cartões | D22: 4232.19 | E22: 4232.19 | G22: Joias Micheli 02/04 | H22: Micheli | I22: Renda Extra | J22: 344 | K22: 344 | N22: C&A | O22: 107.98 | P22: 46032 | Q22: Lila | R22: Mercado Pago | U22: Total | V22: =SUM(V5:V21) -> 600.14 | W22: =SUM(W5:W21)-V22 -> -600.14
B23: Carro | C23: Carro | D23: 1485.11 | E23: 1485.11 | G23: Emprestimo Amor | H23: Anna | I23: Emprestimo | J23: 2000 | K23: 2000 | N23: Emprestimo Cartão 01/04 | O23: 165 | P23: 46032 | Q23: Lila | R23: Mercado Pago
B24: Diversos | C24: Outros | D24: 29.9 | E24: =Tabela323131619222528313736[[#This Row],[PREVISTO]] -> 29.9 | G24: Cashback | H24: Inter | I24: Cashback | J24: 472.77 | K24: =Tabela5911141720232629323840[[#This Row],[PREVISTO]] -> 472.77 | N24: Estacionamento Shopping | O24: 63 | P24: 46032 | Q24: Anna | R24: Mercado Pago
B25: Super Tela | C25: Despesa Pessoal | D25: 30 | E25: 30 | G25: Cartão Emprestimo | H25: Picpay | I25: Pedalada | J25: 4439 | K25: 4439
B26: Júlia Shopping | C26: Familiar | D26: 50 | E26: 50 | G26: Distribuidora | H26: Lucas | I26: Renda Extra | J26: 150 | K26: 150
B27: Carnes - Arlison | C27: Compras | D27: 140 | E27: 140 | G27: Reembolso WKVE | H27: WKVE | I27: Reembolso | J27: 39.6 | K27: 39.6
B28: Cartão NuBank | C28: Cartões | D28: 2000 | E28: 2000
B29: Cofrinho MP | C29: Investimentos | D29: 180 | E29: 180
B30: Corrida Uber | C30: Despesa Pessoal | D30: 15 | E30: 15
B31: Reembolso Italo | C31: WKVE | D31: 39.6 | E31: 39.6

Sheet Fevereiro
B2: RENDIMENTO | D2: SALDO | G2: Total: | J2: =SUM(E4:E8) -> 4007.4 | M2: Cartões | T2: Despesas de Casa
B3: =SUM(Janeiro!B3,K13-E13) -> 4007.4 | G3: Diferença: | J3: =SUM(J2-B3) -> 2.2737368e-12
D4: Inter | E4: 0 | N4: Divida Cartões: | O4: =SUM(N7:R11) -> 6075.44 | T4: DESCRIÇÃO | U4: VENCIMENTO | V4: VALOR | W4: PAGO | X4: TOTAL: | Y4: =SUM(V5:V21) -> 613.67 | AA4: CEMIG
D5: 99Pay | E5: 0 | G5: Renda: | J5: =J16 -> 3540.66 | T5: Internet | V5: 189.9 | X5: PAGO: | Y5: =SUM(W5:W21) -> 0
B6: PREVISTO | D6: NuBank | E6: 0 | N6: Inter | O6: Santander | P6: Mercado Pago | Q6: NuBank | R6: PicPay | T6: Copasa | V6: 98.34 | X6: FALTA: | Y6: =SUM(Y4-Y5) -> 613.67 | AA6: Nº Cliente: | AB6: 7003157185
B7: =SUM(J13-D13)+Janeiro!B3 -> 3961.001 | D7: Mercado Pago | E7: 4007.4 | G7: Investimento | J7: =SUM(J5*15)/100 -> 531.099 | M7: Outros | N7: =SUMIFS(Tabela4101215182124273033394143[Valor],Tabela4101215182124273033394143[Pagador],"Augusto",Tabela4101215182124273033394143[Banco],"Inter") -> 0 | O7: =SUMIFS(Tabela4101215182124273033394143[Valor],Tabela4101215182124273033394143[Pagador],"Augusto",Tabela4101215182124273033394143[Banco],"Santander") -> 0 | P7: =SUMIFS(Tabela4101215182124273033394143[Valor],Tabela4101215182124273033394143[Pagador],"Augusto",Tabela4101215182124273033394143[Banco],"Mercado Pago") -> 0 | Q7: =SUMIFS(Tabela4101215182124273033394143[Valor],Tabela4101215182124273033394143[Pagador],"Augusto",Tabela4101215182124273033394143[Banco],"NuBank") -> 0 | R7: =SUMIFS(Tabela4101215182124273033394143[Valor],Tabela4101215182124273033394143[Pagador],"Augusto",Tabela4101215182124273033394143[Banco],"PicPay") -> 0 | T7: Cemig | V7: 325.43 | AA7: Nº Instalação: | AB7: 3001236814
D8: Carteira | E8: 0 | G8: Depesas | J8: =SUM(K16*65)/100 -> 2301.429 | M8: Amor | N8: =SUMIFS(Tabela4101215182124273033394143[Valor],Tabela4101215182124273033394143[Pagador],"Anna",Tabela4101215182124273033394143[Banco],"Inter") -> 450 | O8: =SUMIFS(Tabela4101215182124273033394143[Valor],Tabela4101215182124273033394143[Pagador],"Anna",Tabela4101215182124273033394143[Banco],"Santander") -> 0 | P8: =SUMIFS(Tabela4101215182124273033394143[Valor],Tabela4101215182124273033394143[Pagador],"Anna",Tabela4101215182124273033394143[Banco],"Mercado Pago") -> 1852.11 | Q8: =SUMIFS(Tabela4101215182124273033394143[Valor],Tabela4101215182124273033394143[Pagador],"Anna",Tabela4101215182124273033394143[Banco],"NuBank") -> 0 | R8: =SUMIFS(Tabela4101215182124273033394143[Valor],Tabela4101215182124273033394143[Pagador],"Anna",Tabela4101215182124273033394143[Banco],"PicPay") -> 0 | X8: DIVISÃO | AA8: CPF: | AB8: 276.006.966-49
D9: Cofrinho | E9: 0 | G9: Diferença mês | J9: =SUM(K13-E13) -> 3978.38 | M9: Lila | N9: =SUMIFS(Tabela4101215182124273033394143[Valor],Tabela4101215182124273033394143[Pagador],"Lila",Tabela4101215182124273033394143[Banco],"Inter") -> 427 | O9: =SUMIFS(Tabela4101215182124273033394143[Valor],Tabela4101215182124273033394143[Pagador],"Lila",Tabela4101215182124273033394143[Banco],"Santander") -> 0 | P9: =SUMIFS(Tabela4101215182124273033394143[Valor],Tabela4101215182124273033394143[Pagador],"Lila",Tabela4101215182124273033394143[Banco],"Mercado Pago") -> 224.63 | Q9: =SUMIFS(Tabela4101215182124273033394143[Valor],Tabela4101215182124273033394143[Pagador],"Lila",Tabela4101215182124273033394143[Banco],"NuBank") -> 0 | R9: =SUMIFS(Tabela4101215182124273033394143[Valor],Tabela4101215182124273033394143[Pagador],"Lila",Tabela4101215182124273033394143[Banco],"PicPay") -> 1762.07 | X9: Augusto | Y9: =((Y4*70)/100)+Y18 -> 429.569
M10: Claudio | N10: =SUMIFS(Tabela4101215182124273033394143[Valor],Tabela4101215182124273033394143[Pagador],"Claudio",Tabela4101215182124273033394143[Banco],"Inter") -> 0 | O10: =SUMIFS(Tabela4101215182124273033394143[Valor],Tabela4101215182124273033394143[Pagador],"Claudio",Tabela4101215182124273033394143[Banco],"Santander") -> 0 | P10: =SUMIFS(Tabela4101215182124273033394143[Valor],Tabela4101215182124273033394143[Pagador],"Claudio",Tabela4101215182124273033394143[Banco],"Mercado Pago") -> 0 | Q10: =SUMIFS(Tabela4101215182124273033394143[Valor],Tabela4101215182124273033394143[Pagador],"Claudio",Tabela4101215182124273033394143[Banco],"NuBank") -> 0 | R10: =SUMIFS(Tabela4101215182124273033394143[Valor],Tabela4101215182124273033394143[Pagador],"Claudio",Tabela4101215182124273033394143[Banco],"PicPay") -> 740.73
M11: Outros | N11: =SUMIFS(Tabela4101215182124273033394143[Valor],Tabela4101215182124273033394143[Pagador],"Outros",Tabela4101215182124273033394143[Banco],"Inter") -> 618.9 | O11: =SUMIFS(Tabela4101215182124273033394143[Valor],Tabela4101215182124273033394143[Pagador],"Outros",Tabela4101215182124273033394143[Banco],"Santander") -> 0 | P11: =SUMIFS(Tabela4101215182124273033394143[Valor],Tabela4101215182124273033394143[Pagador],"Outros",Tabela4101215182124273033394143[Banco],"Mercado Pago") -> 0 | Q11: =SUMIFS(Tabela4101215182124273033394143[Valor],Tabela4101215182124273033394143[Pagador],"Outros",Tabela4101215182124273033394143[Banco],"NuBank") -> 0 | R11: =SUMIFS(Tabela4101215182124273033394143[Valor],Tabela4101215182124273033394143[Pagador],"Outros",Tabela4101215182124273033394143[Banco],"PicPay") -> 0 | X11: Carla | Y11: =((Y4*30)/100)+Y18 -> 184.101
B12: LANÇAMENTOS DO MÊS
B13: Total: | D13: =SUM(D16:D32) -> 17247.14 | E13: =SUM(E16:E32) -> 17247.14 | G13: Total: | J13: =SUM(J16:J31) -> 21179.121 | K13: =SUM(K16:K31) -> 21225.52 | M13: Descrição | N13: Valor | O13: Data | P13: Pagador | Q13: Banco
B14: DESPESAS | G14: RECEBIMENTOS | M14: Emprestimo Inter 05/06 | N14: 450 | O14: 46063 | P14: Anna | Q14: Inter
B15: DESCRIÇÃO | C15: TIPO | D15: PREVISTO | E15: PAGO | G15: DESCRIÇÃO | H15: PAGADOR | I15: TIPO | J15: PREVISTO | K15: RECEBIDO | M15: Prestação HB20s | N15: 1485.11 | O15: 46069 | P15: Anna | Q15: Mercado Pago
B16: Theo | C16: Pensão | D16: 437 | E16: 437 | G16: Salário | H16: WKVE | I16: Renda | J16: 3540.66 | K16: 3540.66 | M16: Plano de saúde | N16: 200 | O16: 46063 | P16: Anna | Q16: Mercado Pago
B17: Plano de Saúde - Mãe | C17: Despesa Pessoal | D17: 158.95 | E17: 158.95 | G17: Aluguel Notebook | H17: WKVE | I17: Renda | J17: 50 | K17: 50 | M17: Plano de saúde Gustavo | N17: 167 | O17: 46063 | P17: Anna | Q17: Mercado Pago
B18: Despesa de casa | C18: Despesas de Casa | D18: =SUM(V6:V21) -> 423.77 | E18: 423.77 | G18: Cartões Emprestados | H18: Lila | I18: Cartão | J18: =SUM(N9:R9) -> 2413.7 | K18: 2414.7 | M18: Emprestimo PicPay | N18: 740.73 | O18: 46063 | P18: Claudio | Q18: PicPay
B19: Mercado Pago | C19: Cartões | D19: 1088.36 | E19: 1088.36 | G19: Cartões Emprestados | H19: Claudio | I19: Cartão | J19: =SUM(N10:R10) -> 740.73 | K19: 740.73 | M19: Cerveja praia 31/12 | N19: 36 | O19: 46060 | P19: Lila | Q19: Inter
B20: Inter | C20: Cartões | D20: 7974.2 | E20: 7974.2 | G20: Cartões Emprestados | H20: Anna | I20: Cartão | J20: =SUM(N8:R8) -> 2302.11 | K20: 2562 | M20: Supermercado 31/12 | N20: 25 | O20: 46060 | P20: Lila | Q20: Inter
B21: Santander | C21: Cartões | D21: 667.2 | E21: 667.2 | G21: Despesa de casa | H21: Carla | I21: Despesas de Casa | J21: =Y11 -> 184.101 | K21: 184.1 | M21: Pastel | N21: 40 | O21: 46060 | P21: Lila | Q21: Inter
B22: PicPay | C22: Cartões | D22: 3118.05 | E22: 3118.05 | G22: Cartões Emprestados | H22: Outros | I22: Cartão | J22: =SUM(N11:R11) -> 618.9 | K22: 620.6 | M22: Supermercado 02/01 | N22: 35 | O22: 46060 | P22: Lila | Q22: Inter | U22: Total | V22: =SUM(V5:V21) -> 613.67 | W22: =SUM(W5:W21)-V22 -> -613.67
B23: Carro | C23: Carro | D23: 1485.11 | E23: 1485.11 | G23: Saque aniversário | H23: FGTS | I23: Renda | J23: 1122.85 | K23: 1122.85 | M23: Cerveja praia 02/01 | N23: 40 | O23: 46060 | P23: Lila | Q23: Inter
B24: Diversos | C24: Outros | D24: 3.2 | E24: =Tabela32313161922252831373634[[#This Row],[PREVISTO]] -> 3.2 | G24: Adiantamento 13º | H24: WKVE | I24: Renda | J24: 2200 | K24: 2243.81 | M24: Supermercado 01/01 | N24: 106 | O24: 46060 | P24: Lila | Q24: Inter
B25: IPVA + Licenciamento | C25: Automóveis | D25: 811.35 | E25: 811.35 | G25: Distribuidora | H25: Lucas | I25: Renda Extra | J25: 350 | K25: =Tabela591114172023262932384042[[#This Row],[PREVISTO]] -> 350 | M25: Restaurante Praia Brava | N25: 120 | O25: 46060 | P25: Lila | Q25: Inter
B26: IPTU | C26: Casa | D26: 680 | E26: 680 | G26: Venda Joias 03/04 | H26: Micheli | I26: Renda Extra | J26: 344 | K26: 344 | M26: Padaria Praia Brava | N26: 25 | O26: 46060 | P26: Lila | Q26: Inter
B27: MinasCap | C27: Jogos | D27: 20 | E27: 20 | G27: Férias | H27: WKVE | I27: Renda | J27: 4720.89 | K27: 4720.89 | M27: Parabrisa Prisma 02/04 | N27: 165 | O27: 46060 | P27: Lila | Q27: Mercado Pago
B28: IPVA Moto | C28: Automóveis | D28: 144.63 | E28: 144.63 | G28: IPTU | H28: Carla | I28: Despesas de Casa | J28: 340 | K28: 80 | M28: Supermercado Angra | N28: 59.63 | O28: 46060 | P28: Lila | Q28: Mercado Pago
B29: Praia | C29: Lazer | D29: 235.32 | E29: =Tabela32313161922252831373634[[#This Row],[PREVISTO]] -> 235.32 | G29: Cofrinho Mercado | H29: Mercado Pago | I29: Investimentos | J29: 689.18 | K29: =Tabela591114172023262932384042[[#This Row],[PREVISTO]] -> 689.18 | M29: Ana (Mãe da Gabi) Airbnb | N29: 103.15 | O29: 46060 | P29: Outros | Q29: Inter
G30: Adiantamento Março | H30: Anna | I30: Despesas de Casa | J30: 1562 | K30: 1562 | M30: Dadi Airbnb | N30: 206.3 | O30: 46060 | P30: Outros | Q30: Inter
M31: Lucas Airbnb | N31: 206.3 | O31: 46060 | P31: Outros | Q31: Inter
M32: Carla | N32: 103.15 | O32: 46060 | P32: Outros | Q32: Inter
M33: Emprestimo Cartão | N33: 1586 | O33: 46063 | P33: Lila | Q33: PicPay
M34: Compra de Ouro 01/03 | N34: 176.07 | O34: 46063 | P34: Lila | Q34: PicPay

Sheet Março
B2: RENDIMENTO | D2: SALDO | G2: Total: | J2: =SUM(E4:E8) -> 0 | M2: Cartões | T2: Despesas de Casa
B3: =SUM(Fevereiro!B3,K13-E13) -> 0 | G3: Diferença: | J3: =SUM(J2-B3) -> 0
D4: Inter | E4: 0 | N4: Divida Cartões: | O4: =SUM(N7:R11) -> 2392.38 | T4: DESCRIÇÃO | U4: VENCIMENTO | V4: VALOR | W4: PAGO | X4: TOTAL: | Y4: =SUM(V5:V21) -> 602.17 | AA4: CEMIG
D5: 99Pay | E5: 0 | G5: Renda: | J5: =J16 -> 0 | T5: Internet | V5: 189.9 | X5: PAGO: | Y5: =SUM(W5:W21) -> 0
B6: PREVISTO | D6: NuBank | E6: 0 | N6: Inter | O6: Santander | P6: Mercado Pago | Q6: NuBank | R6: PicPay | T6: Copasa | V6: 183.33 | X6: FALTA: | Y6: =SUM(Y4-Y5) -> 602.17 | AA6: Nº Cliente: | AB6: 7003157185
B7: =SUM(J13-D13)+Fevereiro!B3 -> -748.969 | D7: Mercado Pago | E7: 0 | G7: Investimento | J7: =SUM(J5*15)/100 -> 0 | M7: Outros | N7: =SUMIFS(Tabela41012151821242730333941436[Valor],Tabela41012151821242730333941436[Pagador],"Augusto",Tabela41012151821242730333941436[Banco],"Inter") -> 0 | O7: =SUMIFS(Tabela41012151821242730333941436[Valor],Tabela41012151821242730333941436[Pagador],"Augusto",Tabela41012151821242730333941436[Banco],"Santander") -> 0 | P7: =SUMIFS(Tabela41012151821242730333941436[Valor],Tabela41012151821242730333941436[Pagador],"Augusto",Tabela41012151821242730333941436[Banco],"Mercado Pago") -> 0 | Q7: =SUMIFS(Tabela41012151821242730333941436[Valor],Tabela41012151821242730333941436[Pagador],"Augusto",Tabela41012151821242730333941436[Banco],"NuBank") -> 0 | R7: =SUMIFS(Tabela41012151821242730333941436[Valor],Tabela41012151821242730333941436[Pagador],"Augusto",Tabela41012151821242730333941436[Banco],"PicPay") -> 0 | T7: Cemig | V7: 228.94 | AA7: Nº Instalação: | AB7: 3001236814
D8: Carteira | E8: 0 | G8: Depesas | J8: =SUM(K16*65)/100 -> 0 | M8: Amor | N8: =SUMIFS(Tabela41012151821242730333941436[Valor],Tabela41012151821242730333941436[Pagador],"Anna",Tabela41012151821242730333941436[Banco],"Inter") -> 0 | O8: =SUMIFS(Tabela41012151821242730333941436[Valor],Tabela41012151821242730333941436[Pagador],"Anna",Tabela41012151821242730333941436[Banco],"Santander") -> 0 | P8: =SUMIFS(Tabela41012151821242730333941436[Valor],Tabela41012151821242730333941436[Pagador],"Anna",Tabela41012151821242730333941436[Banco],"Mercado Pago") -> 1000 | Q8: =SUMIFS(Tabela41012151821242730333941436[Valor],Tabela41012151821242730333941436[Pagador],"Anna",Tabela41012151821242730333941436[Banco],"NuBank") -> 0 | R8: =SUMIFS(Tabela41012151821242730333941436[Valor],Tabela41012151821242730333941436[Pagador],"Anna",Tabela41012151821242730333941436[Banco],"PicPay") -> 0 | X8: DIVISÃO | AA8: CPF: | AB8: 276.006.966-49
D9: Cofrinho | E9: 0 | G9: Diferença mês | J9: =SUM(K13-E13) -> -4007.4 | M9: Lila | N9: =SUMIFS(Tabela41012151821242730333941436[Valor],Tabela41012151821242730333941436[Pagador],"Lila",Tabela41012151821242730333941436[Banco],"Inter") -> 35 | O9: =SUMIFS(Tabela41012151821242730333941436[Valor],Tabela41012151821242730333941436[Pagador],"Lila",Tabela41012151821242730333941436[Banco],"Santander") -> 0 | P9: =SUMIFS(Tabela41012151821242730333941436[Valor],Tabela41012151821242730333941436[Pagador],"Lila",Tabela41012151821242730333941436[Banco],"Mercado Pago") -> 165 | Q9: =SUMIFS(Tabela41012151821242730333941436[Valor],Tabela41012151821242730333941436[Pagador],"Lila",Tabela41012151821242730333941436[Banco],"NuBank") -> 0 | R9: =SUMIFS(Tabela41012151821242730333941436[Valor],Tabela41012151821242730333941436[Pagador],"Lila",Tabela41012151821242730333941436[Banco],"PicPay") -> 418.51 | X9: Augusto | Y9: =((Y4*70)/100)+Y18 -> 421.519
M10: Claudio | N10: =SUMIFS(Tabela41012151821242730333941436[Valor],Tabela41012151821242730333941436[Pagador],"Claudio",Tabela41012151821242730333941436[Banco],"Inter") -> 0 | O10: =SUMIFS(Tabela41012151821242730333941436[Valor],Tabela41012151821242730333941436[Pagador],"Claudio",Tabela41012151821242730333941436[Banco],"Santander") -> 0 | P10: =SUMIFS(Tabela41012151821242730333941436[Valor],Tabela41012151821242730333941436[Pagador],"Claudio",Tabela41012151821242730333941436[Banco],"Mercado Pago") -> 0 | Q10: =SUMIFS(Tabela41012151821242730333941436[Valor],Tabela41012151821242730333941436[Pagador],"Claudio",Tabela41012151821242730333941436[Banco],"NuBank") -> 0 | R10: =SUMIFS(Tabela41012151821242730333941436[Valor],Tabela41012151821242730333941436[Pagador],"Claudio",Tabela41012151821242730333941436[Banco],"PicPay") -> 154.97
M11: Outros | N11: =SUMIFS(Tabela41012151821242730333941436[Valor],Tabela41012151821242730333941436[Pagador],"Outros",Tabela41012151821242730333941436[Banco],"Inter") -> 618.9 | O11: =SUMIFS(Tabela41012151821242730333941436[Valor],Tabela41012151821242730333941436[Pagador],"Outros",Tabela41012151821242730333941436[Banco],"Santander") -> 0 | P11: =SUMIFS(Tabela41012151821242730333941436[Valor],Tabela41012151821242730333941436[Pagador],"Outros",Tabela41012151821242730333941436[Banco],"Mercado Pago") -> 0 | Q11: =SUMIFS(Tabela41012151821242730333941436[Valor],Tabela41012151821242730333941436[Pagador],"Outros",Tabela41012151821242730333941436[Banco],"NuBank") -> 0 | R11: =SUMIFS(Tabela41012151821242730333941436[Valor],Tabela41012151821242730333941436[Pagador],"Outros",Tabela41012151821242730333941436[Banco],"PicPay") -> 0 | X11: Carla | Y11: =((Y4*30)/100)+Y18 -> 180.651
B12: LANÇAMENTOS DO MÊS
B13: Total: | D13: =SUM(D16:D32) -> 15813.1 | E13: =SUM(E16:E32) -> 15016.62 | G13: Total: | J13: =SUM(J16:J31) -> 11056.731 | K13: =SUM(K16:K31) -> 11009.22 | M13: Descrição | N13: Valor | O13: Data | P13: Pagador | Q13: Banco
B14: DESPESAS | G14: RECEBIMENTOS | M14: Carro | N14: 1000 | O14: 46097 | P14: Anna | Q14: Mercado Pago
B15: DESCRIÇÃO | C15: TIPO | D15: PREVISTO | E15: PAGO | G15: DESCRIÇÃO | H15: PAGADOR | I15: TIPO | J15: PREVISTO | K15: RECEBIDO | M15: Cartão emprestado 03/04 | N15: 154.97 | O15: 46375 | P15: Claudio | Q15: PicPay
B16: Theo | C16: Pensão | D16: 468 | E16: 468 | G16: Salário | H16: WKVE | I16: Renda | J16: 0 | M16: Supermercado Angra | N16: 35 | O16: 46024 | P16: Lila | Q16: Inter
B17: Plano de Saúde - Mãe | C17: Despesa Pessoal | D17: 174.96 | E17: 174.96 | G17: Aluguel Notebook | H17: WKVE | I17: Renda | J17: 50 | M17: Abastecimento Gasolina | N17: 100 | O17: 46083 | P17: Lila | Q17: PicPay
B18: Despesa de casa | C18: Despesas de Casa | D18: =SUM(V6:V21) -> 412.27 | G18: Cartões Emprestados | H18: Lila | I18: Cartão | J18: =SUM(N9:R9) -> 618.51 | K18: 621 | M18: Compra Ouro 02/03 | N18: 176.07 | O18: 46048 | P18: Lila | Q18: Picpay
B19: Mercado Pago | C19: Cartões | D19: 917.55 | E19: 917.55 | G19: Cartões Emprestados | H19: Claudio | I19: Cartão | J19: =SUM(N10:R10) -> 154.97 | K19: 154.97 | M19: Leroy Merlin Contagem 01/02 | N19: 142.44 | O19: 46064 | P19: Lila | Q19: PicPay
B20: Inter | C20: Cartões | D20: 4265.29 | E20: 4265.29 | G20: Cartões Emprestados | H20: Anna | I20: Cartão | J20: =SUM(N8:R8) -> 1000 | K20: 1000 | M20: Wilsonaugusto-Parabrisa 03/04 | N20: 165 | O20: 46385 | P20: Lila | Q20: Mercado Pago
B21: Santander | C21: Cartões | D21: 617.2 | E21: 617.2 | G21: Despesa de casa | H21: Carla | I21: Casa | J21: =Y11 -> 180.651 | K21: 180.65 | M21: Ana (Mãe da Gabi) Airbnb | N21: 103.15 | O21: 46060 | P21: Outros | Q21: Inter
B22: PicPay | C22: Cartões | D22: 5536.78 | E22: 5536.78 | G22: Cartões Emprestados | H22: Outros | I22: Cartão | J22: =SUM(N11:R11) -> 618.9 | K22: 618.9 | M22: Dadi Airbnb | N22: 206.3 | O22: 46060 | P22: Outros | Q22: Inter | U22: Total | V22: =SUM(V5:V21) -> 602.17 | W22: =SUM(W5:W21)-V22 -> -602.17
B23: Carro | C23: Carro | D23: 1485.11 | E23: 1485.11 | G23: Cashback | H23: PicPay | I23: Cashback | J23: 310.7 | K23: =Tabela5911141720232629323840425[[#This Row],[PREVISTO]] -> 310.7 | M23: Lucas Airbnb | N23: 206.3 | O23: 46060 | P23: Outros | Q23: Inter
B24: Diversos | C24: Outros | D24: 244.33 | E24: =Tabela323131619222528313736344[[#This Row],[PREVISTO]] -> 244.33 | G24: Recebimento | H24: Distribuidora | I24: Renda Extra | J24: 270 | K24: =Tabela5911141720232629323840425[[#This Row],[PREVISTO]] -> 270 | M24: Carla | N24: 103.15 | O24: 46060 | P24: Outros | Q24: Inter
B25: Distribuidora | C25: Lazer | D25: 496.21 | E25: 250 | G25: Venda Joias 04/04 | H25: Micheli | I25: Vendas | J25: 344 | K25: 344
B26: Praia | C26: Lazer | D26: 138 | G26: IPTU | H26: Carla | I26: Casa | J26: 260 | K26: 260
B27: Binance | C27: Investimento | D27: 100 | E27: 100 | G27: Venda Moto | H27: Venda | I27: Vendas | J27: 6900 | K27: 6900
B28: Emprestimo Jader | C28: Emprestimos | D28: 161.67 | E28: 161.67 | G28: Venda Joias Colar | H28: Micheli | I28: Vendas | J28: 179 | K28: 179
B29: MinasCap | C29: Jogos | D29: 20 | E29: 20 | G29: Emprestimo Jader | H29: Jader | I29: Emprestimo | J29: 170 | K29: 170
B30: IPVA 02/03 | C30: Despesas | D30: 775.73 | E30: 775.73 | G30: Bicos | H30: Distribuidora | I30: Renda Extra

Sheet Abril
B2: RENDIMENTO | D2: SALDO | G2: Total: | J2: =SUM(E4:E8) -> 8691.41 | M2: Cartões | T2: Despesas de Casa
B3: =SUM(Março!B3,K13-E13) -> 8691.41 | G3: Diferença: | J3: =SUM(J2-B3) -> 3.6379788e-12
D4: Inter | E4: 0 | N4: Divida Cartões: | O4: =SUM(N7:R11) -> 3077.41 | T4: DESCRIÇÃO | U4: VENCIMENTO | V4: VALOR | W4: PAGO | X4: TOTAL: | Y4: =SUM(V5:V21) -> 545.49 | AA4: CEMIG
D5: 99Pay | E5: 0 | G5: Renda: | J5: =J16 -> 2953.3 | T5: Internet | V5: 189.9 | X5: PAGO: | Y5: =SUM(W5:W21) -> 0
B6: PREVISTO | D6: NuBank | E6: 0 | N6: Inter | O6: Santander | P6: Mercado Pago | Q6: NuBank | R6: PicPay | T6: Copasa | V6: 114.6 | X6: FALTA: | Y6: =SUM(Y4-Y5) -> 545.49 | AA6: Nº Cliente: | AB6: 7003157185
B7: =SUM(J13-D13)+Março!B3 -> 8642.637 | D7: Mercado Pago | E7: 8691.41 | G7: Investimento | J7: =SUM(J5*15)/100 -> 442.995 | M7: Outros | N7: =SUMIFS(Tabela4101215182124273033394143610[Valor],Tabela4101215182124273033394143610[Pagador],"Augusto",Tabela4101215182124273033394143610[Banco],"Inter") -> 0 | O7: =SUMIFS(Tabela4101215182124273033394143610[Valor],Tabela4101215182124273033394143610[Pagador],"Augusto",Tabela4101215182124273033394143610[Banco],"Santander") -> 0 | P7: =SUMIFS(Tabela4101215182124273033394143610[Valor],Tabela4101215182124273033394143610[Pagador],"Augusto",Tabela4101215182124273033394143610[Banco],"Mercado Pago") -> 0 | Q7: =SUMIFS(Tabela4101215182124273033394143610[Valor],Tabela4101215182124273033394143610[Pagador],"Augusto",Tabela4101215182124273033394143610[Banco],"NuBank") -> 0 | R7: =SUMIFS(Tabela4101215182124273033394143610[Valor],Tabela4101215182124273033394143610[Pagador],"Augusto",Tabela4101215182124273033394143610[Banco],"PicPay") -> 0 | T7: Cemig | V7: 240.99 | AA7: Nº Instalação: | AB7: 3001236814
D8: Carteira | E8: 0 | G8: Depesas | J8: =SUM(K16*65)/100 -> 1919.645 | M8: Amor | N8: =SUMIFS(Tabela4101215182124273033394143610[Valor],Tabela4101215182124273033394143610[Pagador],"Anna",Tabela4101215182124273033394143610[Banco],"Inter") -> 0 | O8: =SUMIFS(Tabela4101215182124273033394143610[Valor],Tabela4101215182124273033394143610[Pagador],"Anna",Tabela4101215182124273033394143610[Banco],"Santander") -> 0 | P8: =SUMIFS(Tabela4101215182124273033394143610[Valor],Tabela4101215182124273033394143610[Pagador],"Anna",Tabela4101215182124273033394143610[Banco],"Mercado Pago") -> 1485 | Q8: =SUMIFS(Tabela4101215182124273033394143610[Valor],Tabela4101215182124273033394143610[Pagador],"Anna",Tabela4101215182124273033394143610[Banco],"NuBank") -> 0 | R8: =SUMIFS(Tabela4101215182124273033394143610[Valor],Tabela4101215182124273033394143610[Pagador],"Anna",Tabela4101215182124273033394143610[Banco],"PicPay") -> 0 | X8: DIVISÃO | AA8: CPF: | AB8: 276.006.966-49
D9: Cofrinho | E9: 0 | G9: Diferença mês | J9: =SUM(K13-E13) -> 8691.41 | M9: Lila | N9: =SUMIFS(Tabela4101215182124273033394143610[Valor],Tabela4101215182124273033394143610[Pagador],"Lila",Tabela4101215182124273033394143610[Banco],"Inter") -> 0 | O9: =SUMIFS(Tabela4101215182124273033394143610[Valor],Tabela4101215182124273033394143610[Pagador],"Lila",Tabela4101215182124273033394143610[Banco],"Santander") -> 0 | P9: =SUMIFS(Tabela4101215182124273033394143610[Valor],Tabela4101215182124273033394143610[Pagador],"Lila",Tabela4101215182124273033394143610[Banco],"Mercado Pago") -> 165 | Q9: =SUMIFS(Tabela4101215182124273033394143610[Valor],Tabela4101215182124273033394143610[Pagador],"Lila",Tabela4101215182124273033394143610[Banco],"NuBank") -> 0 | R9: =SUMIFS(Tabela4101215182124273033394143610[Valor],Tabela4101215182124273033394143610[Pagador],"Lila",Tabela4101215182124273033394143610[Banco],"PicPay") -> 176.07 | X9: Augusto | Y9: =((Y4*70)/100)+Y18 -> 381.843
M10: Jader | N10: =SUMIFS(Tabela4101215182124273033394143610[Valor],Tabela4101215182124273033394143610[Pagador],"Jader",Tabela4101215182124273033394143610[Banco],"Inter") -> 190 | O10: =SUMIFS(Tabela4101215182124273033394143610[Valor],Tabela4101215182124273033394143610[Pagador],"Jader",Tabela4101215182124273033394143610[Banco],"Santander") -> 0 | P10: =SUMIFS(Tabela4101215182124273033394143610[Valor],Tabela4101215182124273033394143610[Pagador],"Jader",Tabela4101215182124273033394143610[Banco],"Mercado Pago") -> 0 | Q10: =SUMIFS(Tabela4101215182124273033394143610[Valor],Tabela4101215182124273033394143610[Pagador],"Jader",Tabela4101215182124273033394143610[Banco],"NuBank") -> 0 | R10: =SUMIFS(Tabela4101215182124273033394143610[Valor],Tabela4101215182124273033394143610[Pagador],"Jader",Tabela4101215182124273033394143610[Banco],"PicPay") -> 442.44
M11: Outros | N11: =SUMIFS(Tabela4101215182124273033394143610[Valor],Tabela4101215182124273033394143610[Pagador],"Outros",Tabela4101215182124273033394143610[Banco],"Inter") -> 618.9 | O11: =SUMIFS(Tabela4101215182124273033394143610[Valor],Tabela4101215182124273033394143610[Pagador],"Outros",Tabela4101215182124273033394143610[Banco],"Santander") -> 0 | P11: =SUMIFS(Tabela4101215182124273033394143610[Valor],Tabela4101215182124273033394143610[Pagador],"Outros",Tabela4101215182124273033394143610[Banco],"Mercado Pago") -> 0 | Q11: =SUMIFS(Tabela4101215182124273033394143610[Valor],Tabela4101215182124273033394143610[Pagador],"Outros",Tabela4101215182124273033394143610[Banco],"NuBank") -> 0 | R11: =SUMIFS(Tabela4101215182124273033394143610[Valor],Tabela4101215182124273033394143610[Pagador],"Outros",Tabela4101215182124273033394143610[Banco],"PicPay") -> 0 | X11: Carla | Y11: =((Y4*30)/100)+Y18 -> 163.647
B12: LANÇAMENTOS DO MÊS
B13: Total: | D13: =SUM(D16:D36) -> 14447.99 | E13: =SUM(E16:E36) -> 14212.4 | G13: Total: | J13: =SUM(J16:J33) -> 23090.627 | K13: =SUM(K16:K33) -> 22903.81 | M13: Descrição | N13: Valor | O13: Data | P13: Pagador | Q13: Banco
B14: DESPESAS | G14: RECEBIMENTOS | M14: Carro | N14: 1485 | O14: 46097 | P14: Anna | Q14: Mercado Pago
B15: DESCRIÇÃO | C15: TIPO | D15: PREVISTO | E15: PAGO | G15: DESCRIÇÃO | H15: PAGADOR | I15: TIPO | J15: PREVISTO | K15: RECEBIDO | M15: Cartão emprestado 04/04 | N15: 154.97 | O15: 46375 | P15: Claudio | Q15: PicPay
B16: Theo | C16: Pensão | D16: 350 | E16: 350 | G16: Salário | H16: WKVE | I16: Renda | J16: 2953.3 | K16: 2953.3 | M16: Compra Ouro 03/03 | N16: 176.07 | O16: 46048 | P16: Lila | Q16: Picpay
B17: Plano de Saúde - Mãe | C17: Despesa Pessoal | D17: 130.43 | E17: 130.43 | G17: Aluguel Notebook | H17: WKVE | I17: Renda | J17: 50 | K17: 50 | M17: Leroy Merlin Contagem 02/02 | N17: 142.44 | O17: 46064 | P17: Jader | Q17: PicPay
B18: Despesa de casa | C18: Despesas de Casa | D18: =SUM(V6:V21) -> 355.59 | E18: 120 | G18: Cartões Emprestados | H18: Lila | I18: Cartão | J18: =SUM(N9:R9) -> 341.07 | K18: 342 | M18: Wilsonaugusto-Parabrisa 04/04 | N18: 165 | O18: 46385 | P18: Lila | Q18: Mercado Pago
B19: Mercado Pago | C19: Cartões | D19: 1356.52 | E19: 1356.52 | G19: Cartões Emprestados | H19: Jader | I19: Cartão | J19: =SUM(N10:R10) -> 632.44 | K19: 632.44 | M19: Ana (Mãe da Gabi) Airbnb 03/06 | N19: 103.15 | O19: 46060 | P19: Outros | Q19: Inter
B20: Inter | C20: Cartões | D20: 3166.46 | E20: 3166.46 | G20: Cartões Emprestados | H20: Anna | I20: Cartão | J20: =SUM(N8:R8) -> 1485 | K20: 1485 | M20: Dadi Airbnb 03/06 | N20: 206.3 | O20: 46060 | P20: Outros | Q20: Inter
B21: Santander | C21: Cartões | D21: 517.2 | E21: 517.2 | G21: Despesa de casa | H21: Carla | I21: Casa | J21: =Y11 -> 163.647 | K21: 163.65 | M21: Lucas Airbnb 03/06 | N21: 206.3 | O21: 46060 | P21: Outros | Q21: Inter
B22: PicPay | C22: Cartões | D22: 3734.35 | E22: 3734.35 | G22: Cartões Emprestados | H22: Outros | I22: Cartão | J22: =SUM(N11:R11) -> 618.9 | K22: 619.15 | M22: Carla 03/06 | N22: 103.15 | O22: 46060 | P22: Outros | Q22: Inter | U22: Total | V22: =SUM(V5:V21) -> 545.49 | W22: =SUM(W5:W21)-V22 -> -545.49
B23: Carro | C23: Carro | D23: 1485.11 | E23: 1485.11 | G23: Cashback | H23: PicPay | I23: Cashback | J23: 112.54 | K23: 112.54 | M23: Jim Com Recal - Jader - 01/10 | N23: 190 | O23: 46093 | P23: Jader | Q23: Inter
B24: Diversos | C24: Outros | D24: 0 | E24: =Tabela3231316192225283137363442[[#This Row],[PREVISTO]] -> 0 | G24: Recebimento | H24: WKVE | I24: Renda Extra | J24: 35 | K24: 35 | M24: Jim.com Recal - Jader - 01/10 | N24: 300 | O24: 46093 | P24: Jader | Q24: PicPay
B25: IPVA 03/03 | C25: Carro | D25: 0 | G25: Venda Joias | H25: Micheli | I25: Renda Extra | J25: 288 | K25: 100
B26: Distribuidora | C26: Despesa Pessoal | D26: 224 | E26: 224 | G26: Venda Joias | H26: Mariana | I26: Renda Extra | J26: 178 | K26: 178
B27: Roça - Pascoa | C27: Despesa Pessoal | D27: 128 | E27: 128 | G27: PicPay | H27: Claudio | J27: 154.97 | K27: 154.97
B28: Materiais Theo 02/02 | C28: Despesa Pessoal | D28: 43 | E28: 43 | G28: Anna - Planos | H28: Anna | I28: Casa | J28: 627 | K28: 627
B29: Mochila - 03/03 | C29: Despesa Pessoal | D29: 50.6 | E29: 50.6 | G29: Emprestimo | H29: Jader | I29: Outros | J29: 2200 | K29: 2200
B30: Festa Theo | C30: Despesa Pessoal | D30: 457.44 | E30: 457.44 | G30: Doce de leite | H30: Moises | I30: Outros | J30: 20 | K30: 20
B31: Doce de leite | C31: Despesa Pessoal | D31: 40 | E31: 40 | G31: Venda Joias | H31: Débora | I31: Renda Extra | J31: 95 | K31: 95
B32: IPTU restante | C32: Despesa Pessoal | D32: 103.29 | E32: 103.29 | G32: Crédito Cartão | H32: Inter | I32: Outros | J32: 13000.94 | K32: =Tabela59111417202326293238404259[[#This Row],[PREVISTO]] -> 13000.94
B33: Celular novo | C33: Despesa Pessoal | D33: 1400 | E33: 1400 | G33: Chashback MP | H33: Mercado Pago | I33: Rendimentos | J33: 134.82 | K33: =Tabela59111417202326293238404259[[#This Row],[PREVISTO]] -> 134.82
B34: Rparo Joias Debora | C34: Outros | D34: 130 | E34: 130
B35: Investimento | C35: Investimento | D35: 500 | E35: 500
B36: Emprestimo - Anna | C36: Emprestimos | D36: 276 | E36: 276

Sheet Maio
B2: RENDIMENTO | D2: SALDO | G2: Total: | J2: =SUM(E4:E8) -> 2041.03 | M2: Cartões | T2: Despesas de Casa
B3: =SUM(Abril!B3,K13-E13) -> 2041.03 | G3: Diferença: | J3: =SUM(J2-B3) -> 3.8653525e-12
D4: Inter | E4: 0 | N4: Divida Cartões: | O4: =SUM(N7:R11) -> 3241.31 | T4: DESCRIÇÃO | U4: VENCIMENTO | V4: VALOR | W4: PAGO | X4: TOTAL: | Y4: =SUM(V5:V21) -> 604.61 | AA4: CEMIG
D5: 99Pay | E5: 0 | G5: Renda: | J5: =J16 -> 3577.98 | T5: Internet | V5: 189.9 | X5: PAGO: | Y5: =SUM(W5:W21) -> 0
B6: PREVISTO | D6: NuBank | E6: 0 | N6: Inter | O6: Santander | P6: Mercado Pago | Q6: NuBank | R6: PicPay | T6: Copasa | V6: 148.54 | X6: FALTA: | Y6: =SUM(Y4-Y5) -> 604.61 | AA6: Nº Cliente: | AB6: 7003157185
B7: =SUM(J13-D13)+Abril!B3 -> 3720.343 | D7: Mercado Pago | E7: 2041.03 | G7: Investimento | J7: =SUM(J5*15)/100 -> 536.697 | M7: Paula | N7: =SUMIFS(Tabela41012151821242730333941436103[Valor],Tabela41012151821242730333941436103[Pagador],"Paula",Tabela41012151821242730333941436103[Banco],"Inter") -> 0 | O7: =SUMIFS(Tabela41012151821242730333941436103[Valor],Tabela41012151821242730333941436103[Pagador],"Paula",Tabela41012151821242730333941436103[Banco],"Santander") -> 0 | P7: =SUMIFS(Tabela41012151821242730333941436103[Valor],Tabela41012151821242730333941436103[Pagador],"Paula",Tabela41012151821242730333941436103[Banco],"Mercado Pago") -> 0 | Q7: =SUMIFS(Tabela41012151821242730333941436103[Valor],Tabela41012151821242730333941436103[Pagador],"Paula",Tabela41012151821242730333941436103[Banco],"NuBank") -> 0 | R7: =SUMIFS(Tabela41012151821242730333941436103[Valor],Tabela41012151821242730333941436103[Pagador],"Paula",Tabela41012151821242730333941436103[Banco],"PicPay") -> 0 | T7: Cemig | V7: 266.17 | AA7: Nº Instalação: | AB7: 3001236814
D8: Carteira | E8: 0 | G8: Depesas | J8: =SUM(K16*65)/100 -> 2325.687 | M8: Amor | N8: =SUMIFS(Tabela41012151821242730333941436103[Valor],Tabela41012151821242730333941436103[Pagador],"Anna",Tabela41012151821242730333941436103[Banco],"Inter") -> 0 | O8: =SUMIFS(Tabela41012151821242730333941436103[Valor],Tabela41012151821242730333941436103[Pagador],"Anna",Tabela41012151821242730333941436103[Banco],"Santander") -> 0 | P8: =SUMIFS(Tabela41012151821242730333941436103[Valor],Tabela41012151821242730333941436103[Pagador],"Anna",Tabela41012151821242730333941436103[Banco],"Mercado Pago") -> 1928 | Q8: =SUMIFS(Tabela41012151821242730333941436103[Valor],Tabela41012151821242730333941436103[Pagador],"Anna",Tabela41012151821242730333941436103[Banco],"NuBank") -> 0 | R8: =SUMIFS(Tabela41012151821242730333941436103[Valor],Tabela41012151821242730333941436103[Pagador],"Anna",Tabela41012151821242730333941436103[Banco],"PicPay") -> 0 | X8: DIVISÃO | AA8: CPF: | AB8: 276.006.966-49
G9: Diferença mês | J9: =SUM(K13-E13) -> -6650.38 | M9: Lila | N9: =SUMIFS(Tabela41012151821242730333941436103[Valor],Tabela41012151821242730333941436103[Pagador],"Lila",Tabela41012151821242730333941436103[Banco],"Inter") -> 0 | O9: =SUMIFS(Tabela41012151821242730333941436103[Valor],Tabela41012151821242730333941436103[Pagador],"Lila",Tabela41012151821242730333941436103[Banco],"Santander") -> 0 | P9: =SUMIFS(Tabela41012151821242730333941436103[Valor],Tabela41012151821242730333941436103[Pagador],"Lila",Tabela41012151821242730333941436103[Banco],"Mercado Pago") -> 34.4 | Q9: =SUMIFS(Tabela41012151821242730333941436103[Valor],Tabela41012151821242730333941436103[Pagador],"Lila",Tabela41012151821242730333941436103[Banco],"NuBank") -> 0 | R9: =SUMIFS(Tabela41012151821242730333941436103[Valor],Tabela41012151821242730333941436103[Pagador],"Lila",Tabela41012151821242730333941436103[Banco],"PicPay") -> 170.01 | X9: Augusto | Y9: =((Y4*70)/100)+Y18 -> 423.227
M10: Jader | N10: =SUMIFS(Tabela41012151821242730333941436103[Valor],Tabela41012151821242730333941436103[Pagador],"Jader",Tabela41012151821242730333941436103[Banco],"Inter") -> 190 | O10: =SUMIFS(Tabela41012151821242730333941436103[Valor],Tabela41012151821242730333941436103[Pagador],"Jader",Tabela41012151821242730333941436103[Banco],"Santander") -> 0 | P10: =SUMIFS(Tabela41012151821242730333941436103[Valor],Tabela41012151821242730333941436103[Pagador],"Jader",Tabela41012151821242730333941436103[Banco],"Mercado Pago") -> 0 | Q10: =SUMIFS(Tabela41012151821242730333941436103[Valor],Tabela41012151821242730333941436103[Pagador],"Jader",Tabela41012151821242730333941436103[Banco],"NuBank") -> 0 | R10: =SUMIFS(Tabela41012151821242730333941436103[Valor],Tabela41012151821242730333941436103[Pagador],"Jader",Tabela41012151821242730333941436103[Banco],"PicPay") -> 300
M11: Outros | N11: =SUMIFS(Tabela41012151821242730333941436103[Valor],Tabela41012151821242730333941436103[Pagador],"Outros",Tabela41012151821242730333941436103[Banco],"Inter") -> 618.9 | O11: =SUMIFS(Tabela41012151821242730333941436103[Valor],Tabela41012151821242730333941436103[Pagador],"Outros",Tabela41012151821242730333941436103[Banco],"Santander") -> 0 | P11: =SUMIFS(Tabela41012151821242730333941436103[Valor],Tabela41012151821242730333941436103[Pagador],"Outros",Tabela41012151821242730333941436103[Banco],"Mercado Pago") -> 0 | Q11: =SUMIFS(Tabela41012151821242730333941436103[Valor],Tabela41012151821242730333941436103[Pagador],"Outros",Tabela41012151821242730333941436103[Banco],"NuBank") -> 0 | R11: =SUMIFS(Tabela41012151821242730333941436103[Valor],Tabela41012151821242730333941436103[Pagador],"Outros",Tabela41012151821242730333941436103[Banco],"PicPay") -> 0 | X11: Carla | Y11: =((Y4*30)/100)+Y18 -> 181.383
B12: LANÇAMENTOS DO MÊS
B13: Total: | D13: =SUM(D16:D34) -> 14323.1 | E13: =SUM(E16:E34) -> 14323.1 | G13: Total: | J13: =SUM(J16:J34) -> 9352.033 | K13: =SUM(K16:K34) -> 7672.72 | M13: Descrição | N13: Valor | O13: Data | P13: Pagador | Q13: Banco
B14: DESPESAS | G14: RECEBIMENTOS | M14: Carro | N14: 1485 | O14: 46097 | P14: Anna | Q14: Mercado Pago
B15: DESCRIÇÃO | C15: TIPO | D15: PREVISTO | E15: PAGO | G15: DESCRIÇÃO | H15: PAGADOR | I15: TIPO | J15: PREVISTO | K15: RECEBIDO | M15: Ana (Mãe da Gabi) Airbnb 04/06 | N15: 103.15 | O15: 46060 | P15: Outros | Q15: Inter
B16: Theo | C16: Pensão | D16: 464.25 | E16: 464.25 | G16: Salário | H16: WKVE | I16: Renda | J16: 3577.98 | K16: 3577.98 | M16: Dadi Airbnb 04/06 | N16: 206.3 | O16: 46060 | P16: Outros | Q16: Inter
B17: Plano de Saúde - Mãe | C17: Despesa Pessoal | D17: 178.57 | E17: 178.57 | G17: Aluguel Notebook | H17: WKVE | I17: Renda | J17: 50 | K17: 50 | M17: Lucas Airbnb 04/06 | N17: 206.3 | O17: 46060 | P17: Outros | Q17: Inter
B18: Despesa de casa | C18: Despesas de Casa | D18: =SUM(V6:V21) -> 414.71 | E18: 414.71 | G18: Cartões Emprestados | H18: Lila | I18: Cartão | J18: =SUM(N9:R9) -> 204.41 | K18: 171 | M18: Carla 04/06 | N18: 103.15 | O18: 46060 | P18: Outros | Q18: Inter
B19: Mercado Pago | C19: Cartões | D19: 1399.26 | E19: 1399.26 | G19: Venda iPhone 11 - 01/05 | H19: Paula | I19: Cartão | J19: =SUM(N7:R7) -> 0 | M19: Jim Com Recal - Jader - 02/10 | N19: 190 | O19: 46093 | P19: Jader | Q19: Inter
B20: Inter | C20: Cartões | D20: 0 | G20: Cartões Emprestados | H20: Jader | I20: Cartão | J20: =SUM(N10:R10) -> 490 | K20: 490 | M20: Jim.com Recal - Jader - 02/10 | N20: 300 | O20: 46093 | P20: Jader | Q20: PicPay
B21: Santander | C21: Cartões | D21: 0 | G21: Cartões Emprestados | H21: Anna | I21: Cartão | J21: =SUM(N8:R8) -> 1928 | K21: 493 | M21: Máquina de lavar - Lila - 01/10 | N21: 170.01 | O21: 46131 | P21: Lila | Q21: PicPay
B22: PicPay | C22: Cartões | D22: 3397.09 | E22: 3397.09 | G22: Despesa de casa | H22: Carla | I22: Casa | J22: =Y11 -> 181.383 | K22: 233.02 | M22: Emprestimo - Joias | N22: 276 | O22: 46152 | P22: Anna | Q22: Mercado Pago | U22: Total | V22: =SUM(V5:V21) -> 604.61 | W22: =SUM(W5:W21)-V22 -> -604.61
B23: Carro | C23: Carro | D23: 1485.11 | E23: 1485.11 | G23: Cartões Emprestados | H23: Outros | I23: Cartão | J23: =SUM(N11:R11) -> 618.9 | K23: 618.9 | M23: Plano de Saúde - Gustavo | N23: 167 | O23: 46152 | P23: Anna | Q23: Mercado Pago
B24: Diversos | C24: Outros | D24: 786.67 | E24: =Tabela32313[[#This Row],[PREVISTO]] -> 786.67 | G24: Cashback | H24: PicPay | I24: Cashback | J24: 112.54 | M24: Uber Lila | N24: 34.4 | O24: 46152 | P24: Lila | Q24: Mercado Pago
B25: Pagamento ART - WKVE | C25: Outros | D25: 108.39 | E25: 108.39 | G25: Recebimento | H25: Distribuidora | I25: Renda Extra | J25: 0
B26: Iphone 13 Pro Max | C26: Compras | D26: 1400 | E26: 1400 | G26: Reparo berloque | H26: Debora | I26: Vendas | J26: 290 | K26: 290
B27: Reboque - Prisma | C27: Outros | D27: 150 | E27: 150 | G27: Joias | H27: Micheli | I27: Vendas | J27: 188 | K27: 188
B28: Investimento | C28: Investimento | D28: 315 | E28: 315 | G28: Reparo Anel Micheli | H28: Micheli | I28: Vendas | J28: 49 | K28: 49
B29: Multa Lei-seca | C29: Prejuízo | D29: 2934.7 | E29: 2934.7 | G29: Venda iPhone 11 - 01/05 | H29: Anna e Paula | I29: Vendas | J29: 300 | K29: 150
B30: Pátio | C30: Prejuízo | D30: 376.35 | E30: 376.35 | G30: Reembolso WKVE | H30: Outros | I30: Outros | J30: 108.39 | K30: 108.39
B31: Fotógrafo Batizado | C31: Outros | D31: 190 | E31: 190 | G31: Reboque - Prisma | H31: Lila | I31: Outros | J31: 150 | K31: 150
B32: Emprestimo Anna - 29/05 | C32: Emprestimos | D32: 500 | E32: 500 | G32: Pagamento - Emprestimo | H32: Anna | I32: Reembolso | J32: 130 | K32: 130
B33: Emprestimo Anna - 27/05 | C33: Emprestimos | D33: 223 | E33: 223 | G33: Bicos | H33: Distribuidora | I33: Renda Extra | J33: 110 | K33: 110
B34: Emprestimo Anna - | G34: Restituição IR | H34: RF | I34: Outros | J34: 863.43 | K34: 863.43

Sheet Junho
B2: RENDIMENTO | D2: SALDO | G2: Total: | J2: =SUM(E4:E8) -> 1023.97 | M2: Cartões | T2: Despesas de Casa
B3: =SUM(Maio!B3,K13-E13) -> 1023.97 | G3: Diferença: | J3: =SUM(J2-B3) -> 3.4106051e-12
D4: Inter | E4: 0 | N4: Divida Cartões: | O4: =SUM(N7:R11) -> 4098.6 | T4: DESCRIÇÃO | U4: VENCIMENTO | V4: VALOR | W4: PAGO | X4: TOTAL: | Y4: =SUM(V5:V21) -> 640.06 | AA4: CEMIG
D5: 99Pay | E5: 0 | G5: Renda: | J5: =J16 -> 3831.57 | T5: Internet | V5: 189.9 | X5: PAGO: | Y5: =SUM(W5:W21) -> 0
B6: PREVISTO | D6: NuBank | E6: 0 | N6: Inter | O6: Santander | P6: Mercado Pago | Q6: NuBank | R6: PicPay | T6: Copasa | V6: 146.06 | X6: FALTA: | Y6: =SUM(Y4-Y5) -> 640.06 | AA6: Nº Cliente: | AB6: 7003157185
B7: =SUM(J13-D13)+Maio!B3 -> 1073.718 | D7: Mercado Pago | E7: 1023.97 | G7: Investimento | J7: =SUM(J5*15)/100 -> 574.7355 | M7: Paula | N7: =SUMIFS(Tabela4101215182124273033394143610315[Valor],Tabela4101215182124273033394143610315[Pagador],"Paula",Tabela4101215182124273033394143610315[Banco],"Inter") -> 0 | O7: =SUMIFS(Tabela4101215182124273033394143610315[Valor],Tabela4101215182124273033394143610315[Pagador],"Paula",Tabela4101215182124273033394143610315[Banco],"Santander") -> 0 | P7: =SUMIFS(Tabela4101215182124273033394143610315[Valor],Tabela4101215182124273033394143610315[Pagador],"Paula",Tabela4101215182124273033394143610315[Banco],"Mercado Pago") -> 300 | Q7: =SUMIFS(Tabela4101215182124273033394143610315[Valor],Tabela4101215182124273033394143610315[Pagador],"Paula",Tabela4101215182124273033394143610315[Banco],"NuBank") -> 0 | R7: =SUMIFS(Tabela4101215182124273033394143610315[Valor],Tabela4101215182124273033394143610315[Pagador],"Paula",Tabela4101215182124273033394143610315[Banco],"PicPay") -> 0 | T7: Cemig | V7: 304.1 | AA7: Nº Instalação: | AB7: 3001236814
D8: Carteira | E8: 0 | G8: Depesas | J8: =SUM(K16*65)/100 -> 2490.5205 | M8: Amor | N8: =SUMIFS(Tabela4101215182124273033394143610315[Valor],Tabela4101215182124273033394143610315[Pagador],"Anna",Tabela4101215182124273033394143610315[Banco],"Inter") -> 0 | O8: =SUMIFS(Tabela4101215182124273033394143610315[Valor],Tabela4101215182124273033394143610315[Pagador],"Anna",Tabela4101215182124273033394143610315[Banco],"Santander") -> 0 | P8: =SUMIFS(Tabela4101215182124273033394143610315[Valor],Tabela4101215182124273033394143610315[Pagador],"Anna",Tabela4101215182124273033394143610315[Banco],"Mercado Pago") -> 2375 | Q8: =SUMIFS(Tabela4101215182124273033394143610315[Valor],Tabela4101215182124273033394143610315[Pagador],"Anna",Tabela4101215182124273033394143610315[Banco],"NuBank") -> 0 | R8: =SUMIFS(Tabela4101215182124273033394143610315[Valor],Tabela4101215182124273033394143610315[Pagador],"Anna",Tabela4101215182124273033394143610315[Banco],"PicPay") -> 0 | X8: DIVISÃO | AA8: CPF: | AB8: 276.006.966-49
G9: Diferença mês | J9: =SUM(K13-E13) -> -1017.06 | M9: Lila | N9: =SUMIFS(Tabela4101215182124273033394143610315[Valor],Tabela4101215182124273033394143610315[Pagador],"Lila",Tabela4101215182124273033394143610315[Banco],"Inter") -> 0 | O9: =SUMIFS(Tabela4101215182124273033394143610315[Valor],Tabela4101215182124273033394143610315[Pagador],"Lila",Tabela4101215182124273033394143610315[Banco],"Santander") -> 0 | P9: =SUMIFS(Tabela4101215182124273033394143610315[Valor],Tabela4101215182124273033394143610315[Pagador],"Lila",Tabela4101215182124273033394143610315[Banco],"Mercado Pago") -> 0 | Q9: =SUMIFS(Tabela4101215182124273033394143610315[Valor],Tabela4101215182124273033394143610315[Pagador],"Lila",Tabela4101215182124273033394143610315[Banco],"NuBank") -> 0 | R9: =SUMIFS(Tabela4101215182124273033394143610315[Valor],Tabela4101215182124273033394143610315[Pagador],"Lila",Tabela4101215182124273033394143610315[Banco],"PicPay") -> 170.01 | X9: Augusto | Y9: =((Y4*70)/100)+Y18 -> 448.042
M10: Jader | N10: =SUMIFS(Tabela4101215182124273033394143610315[Valor],Tabela4101215182124273033394143610315[Pagador],"Jader",Tabela4101215182124273033394143610315[Banco],"Inter") -> 190 | O10: =SUMIFS(Tabela4101215182124273033394143610315[Valor],Tabela4101215182124273033394143610315[Pagador],"Jader",Tabela4101215182124273033394143610315[Banco],"Santander") -> 0 | P10: =SUMIFS(Tabela4101215182124273033394143610315[Valor],Tabela4101215182124273033394143610315[Pagador],"Jader",Tabela4101215182124273033394143610315[Banco],"Mercado Pago") -> 0 | Q10: =SUMIFS(Tabela4101215182124273033394143610315[Valor],Tabela4101215182124273033394143610315[Pagador],"Jader",Tabela4101215182124273033394143610315[Banco],"NuBank") -> 0 | R10: =SUMIFS(Tabela4101215182124273033394143610315[Valor],Tabela4101215182124273033394143610315[Pagador],"Jader",Tabela4101215182124273033394143610315[Banco],"PicPay") -> 300
M11: Outros | N11: =SUMIFS(Tabela4101215182124273033394143610315[Valor],Tabela4101215182124273033394143610315[Pagador],"Outros",Tabela4101215182124273033394143610315[Banco],"Inter") -> 618.9 | O11: =SUMIFS(Tabela4101215182124273033394143610315[Valor],Tabela4101215182124273033394143610315[Pagador],"Outros",Tabela4101215182124273033394143610315[Banco],"Santander") -> 0 | P11: =SUMIFS(Tabela4101215182124273033394143610315[Valor],Tabela4101215182124273033394143610315[Pagador],"Outros",Tabela4101215182124273033394143610315[Banco],"Mercado Pago") -> 100 | Q11: =SUMIFS(Tabela4101215182124273033394143610315[Valor],Tabela4101215182124273033394143610315[Pagador],"Outros",Tabela4101215182124273033394143610315[Banco],"NuBank") -> 0 | R11: =SUMIFS(Tabela4101215182124273033394143610315[Valor],Tabela4101215182124273033394143610315[Pagador],"Outros",Tabela4101215182124273033394143610315[Banco],"PicPay") -> 44.69 | X11: Carla | Y11: =((Y4*30)/100)+Y18 -> 192.018
B12: LANÇAMENTOS DO MÊS
B13: Total: | D13: =SUM(D16:D31) -> 9539.5 | E13: =SUM(E16:E31) -> 9539.5 | G13: Total: | J13: =SUM(J16:J28) -> 8572.188 | K13: =SUM(K16:K28) -> 8522.44 | M13: Descrição | N13: Valor | O13: Data | P13: Pagador | Q13: Banco
B14: DESPESAS | G14: RECEBIMENTOS | M14: Carro | N14: 1485 | O14: 46097 | P14: Anna | Q14: Mercado Pago
B15: DESCRIÇÃO | C15: TIPO | D15: PREVISTO | E15: PAGO | G15: DESCRIÇÃO | H15: PAGADOR | I15: TIPO | J15: PREVISTO | K15: RECEBIDO | M15: Plano de Saúde - Gustavo | N15: 167 | O15: 46152 | P15: Anna | Q15: Mercado Pago
B16: Theo | C16: Pensão | D16: 444.25 | E16: 444.25 | G16: Salário | H16: WKVE | I16: Renda | J16: 3831.57 | K16: 3831.57 | M16: Emprestimo - Anna | N16: 723 | O16: 46152 | P16: Anna | Q16: Mercado Pago
B17: Plano de Saúde - Mãe | C17: Despesa Pessoal | D17: 142.44 | E17: 142.44 | G17: Aluguel Notebook | H17: WKVE | I17: Renda | J17: 50 | K17: 50 | M17: Jim Com Recal - Jader - 03/10 | N17: 190 | O17: 46093 | P17: Jader | Q17: Inter
B18: Despesa de casa | C18: Despesas de Casa | D18: =SUM(V6:V21) -> 450.16 | E18: 450.16 | G18: Cartões Emprestados | H18: Lila | I18: Cartão | J18: =SUM(N9:R9) -> 170.01 | K18: 170.01 | M18: Jim.com Recal - Jader - 03/10 | N18: 300 | O18: 46093 | P18: Jader | Q18: PicPay
B19: Mercado Pago | C19: Cartões | D19: 1415.59 | E19: 1415.59 | G19: Venda iPhone 11 - 01/05 | H19: Paula | I19: Cartão | J19: =SUM(N7:R7) -> 300 | K19: 300 | M19: Máquina de lavar - Lila - 02/10 | N19: 170.01 | O19: 46131 | P19: Lila | Q19: PicPay
B20: PicPay | C20: Cartões | D20: 3872.43 | E20: 3872.43 | G20: Cartões Emprestados | H20: Jader | I20: Cartão | J20: =SUM(N10:R10) -> 490 | K20: 490 | M20: Ana (Mãe da Gabi) Airbnb 05/06 | N20: 103.15 | O20: 46060 | P20: Outros | Q20: Inter
B21: Carro | C21: Carro | D21: 1485.11 | E21: 1485.11 | G21: Cartões Emprestados | H21: Anna | I21: Cartão | J21: =SUM(N8:R8) -> 2375 | K21: 2375 | M21: Dadi Airbnb 05/06 | N21: 206.3 | O21: 46060 | P21: Outros | Q21: Inter
B22: Diversos | C22: Outros | D22: 815.52 | E22: =D22 -> 815.52 | G22: Despesa de casa | H22: Carla | I22: Casa | J22: =Y11 -> 192.018 | K22: 192.02 | M22: Lucas Airbnb 05/06 | N22: 206.3 | O22: 46060 | P22: Outros | Q22: Inter | U22: Total | V22: =SUM(V5:V21) -> 640.06 | W22: =SUM(W5:W21)-V22 -> -640.06
B23: Pedro | C23: Outros | D23: 35 | E23: 35 | G23: Cartões Emprestados | H23: Outros | I23: Cartão | J23: =SUM(N11:R11) -> 763.59 | K23: 713.84 | M23: Carla 05/06 | N23: 103.15 | O23: 46060 | P23: Outros | Q23: Inter
B24: Porta Sala | C24: Reforma | D24: 879 | E24: 879 | G24: Cashback | H24: PicPay | I24: Cashback | M24: Dia das Mães | N24: 100 | O24: 46149 | P24: Outros | Q24: Mercado Pago
G25: Recebimento | H25: Distribuidora | I25: Renda Extra | M25: Auto Bits - Moises - 01/04 | N25: 44.69 | O25: 46171 | P25: Outros | Q25: PicPay
G26: Venda iPhone 11 - 02/05 | H26: Anna e Paula | I26: Vendas | J26: 300 | K26: 300 | M26: DY MOTOS | N26: 300 | O26: 46162 | P26: Paula | Q26: Mercado Pago
G27: Dia das mães | H27: Pedro/Carla | I27: Outros | J27: 100 | K27: 100

Sheet Julho
B2: RENDIMENTO | D2: SALDO | G2: Total: | J2: =SUM(E4:E8) -> 4770.16 | M2: Cartões | T2: Despesas de Casa
B3: =SUM(Junho!B3,K13-E13) -> 4770.16 | G3: Diferença: | J3: =SUM(J2-B3) -> 3.6379788e-12
D4: Inter | E4: 0 | N4: Divida Cartões: | O4: =SUM(N7:R11) -> 3319.6 | T4: DESCRIÇÃO | U4: VENCIMENTO | V4: VALOR | W4: PAGO | X4: TOTAL: | Y4: =SUM(V5:V21) -> 460.53 | AA4: CEMIG
D5: 99Pay | E5: 0 | G5: Renda: | J5: =J16 -> 3899.22 | T5: Internet | V5: 189.9 | X5: PAGO: | Y5: =SUM(W5:W21) -> 0
B6: PREVISTO | D6: NuBank | E6: 0 | N6: Inter | O6: Santander | P6: Mercado Pago | Q6: NuBank | R6: PicPay | T6: Copasa | V6: 90.92 | X6: FALTA: | Y6: =SUM(Y4-Y5) -> 460.53 | AA6: Nº Cliente: | AB6: 7003157185
B7: =SUM(J13-D13)+Junho!B3 -> 1584.839 | D7: Mercado Pago | E7: 4770.16 | G7: Investimento | J7: =SUM(J5*15)/100 -> 584.883 | M7: Paula | N7: =SUMIFS(Tabela410121518212427303339414361031518[Valor],Tabela410121518212427303339414361031518[Pagador],"Paula",Tabela410121518212427303339414361031518[Banco],"Inter") -> 0 | O7: =SUMIFS(Tabela410121518212427303339414361031518[Valor],Tabela410121518212427303339414361031518[Pagador],"Paula",Tabela410121518212427303339414361031518[Banco],"Santander") -> 0 | P7: =SUMIFS(Tabela410121518212427303339414361031518[Valor],Tabela410121518212427303339414361031518[Pagador],"Paula",Tabela410121518212427303339414361031518[Banco],"Mercado Pago") -> 300 | Q7: =SUMIFS(Tabela410121518212427303339414361031518[Valor],Tabela410121518212427303339414361031518[Pagador],"Paula",Tabela410121518212427303339414361031518[Banco],"NuBank") -> 0 | R7: =SUMIFS(Tabela410121518212427303339414361031518[Valor],Tabela410121518212427303339414361031518[Pagador],"Paula",Tabela410121518212427303339414361031518[Banco],"PicPay") -> 0 | T7: Cemig | V7: 179.71 | AA7: Nº Instalação: | AB7: 3001236814
D8: Carteira | E8: 0 | G8: Depesas | J8: =SUM(K16*65)/100 -> 2534.493 | M8: Amor | N8: =SUMIFS(Tabela410121518212427303339414361031518[Valor],Tabela410121518212427303339414361031518[Pagador],"Anna",Tabela410121518212427303339414361031518[Banco],"Inter") -> 0 | O8: =SUMIFS(Tabela410121518212427303339414361031518[Valor],Tabela410121518212427303339414361031518[Pagador],"Anna",Tabela410121518212427303339414361031518[Banco],"Santander") -> 0 | P8: =SUMIFS(Tabela410121518212427303339414361031518[Valor],Tabela410121518212427303339414361031518[Pagador],"Anna",Tabela410121518212427303339414361031518[Banco],"Mercado Pago") -> 1696 | Q8: =SUMIFS(Tabela410121518212427303339414361031518[Valor],Tabela410121518212427303339414361031518[Pagador],"Anna",Tabela410121518212427303339414361031518[Banco],"NuBank") -> 0 | R8: =SUMIFS(Tabela410121518212427303339414361031518[Valor],Tabela410121518212427303339414361031518[Pagador],"Anna",Tabela410121518212427303339414361031518[Banco],"PicPay") -> 0 | X8: DIVISÃO | AA8: CPF: | AB8: 276.006.966-49
G9: Diferença mês | J9: =SUM(K13-E13) -> 3746.19 | M9: Lila | N9: =SUMIFS(Tabela410121518212427303339414361031518[Valor],Tabela410121518212427303339414361031518[Pagador],"Lila",Tabela410121518212427303339414361031518[Banco],"Inter") -> 0 | O9: =SUMIFS(Tabela410121518212427303339414361031518[Valor],Tabela410121518212427303339414361031518[Pagador],"Lila",Tabela410121518212427303339414361031518[Banco],"Santander") -> 0 | P9: =SUMIFS(Tabela410121518212427303339414361031518[Valor],Tabela410121518212427303339414361031518[Pagador],"Lila",Tabela410121518212427303339414361031518[Banco],"Mercado Pago") -> 0 | Q9: =SUMIFS(Tabela410121518212427303339414361031518[Valor],Tabela410121518212427303339414361031518[Pagador],"Lila",Tabela410121518212427303339414361031518[Banco],"NuBank") -> 0 | R9: =SUMIFS(Tabela410121518212427303339414361031518[Valor],Tabela410121518212427303339414361031518[Pagador],"Lila",Tabela410121518212427303339414361031518[Banco],"PicPay") -> 170.01 | X9: Augusto | Y9: =((Y4*70)/100)+Y18 -> 322.371
